<mujoco model="robot">
  <default>
    <default class="robot/"/>
    </default>
  <worldbody>
    <body name="body_chassis_" pos="0 0 0.67390000000000005" euler="0 0 0">
      <camera name="camera_track_chassis_" class="robot/" mode="track" pos="0 -3 1" zaxis="0 -1 0.5"/>
      <geom name="geom_chassis_" class="robot/" type="box" size="0.10000000000000001 0.20000000000000001 0.22" mass="7.5"/>
      <site name="right_site_chassis_" class="robot/" size="9.9999999999999995e-07 9.9999999999999995e-07 9.9999999999999995e-07" pos="0 -0.20000000000000001 -0.59140000000000004"/>
      <body pos="0 -0.20000000000000001 -0.59140000000000004" name="right_tire/">
        <body name="right_tire/body_tire_right">
          <geom name="right_tire/geom_tire_right" class="robot/" type="cylinder" condim="6" priority="1" size="0.1016 0.029999999999999999" friction="0.25 0.0050000000000000001 0.0001" mass="0.34999999999999998" pos="0 -0.029999999999999999 0" euler="90 0 0"/>
          <joint name="right_tire/joint_tire_right" class="robot/" type="hinge" axis="0 1 0" damping="0.25"/>
        </body>
      </body>
      <site name="left_site_chassis_" class="robot/" size="9.9999999999999995e-07 9.9999999999999995e-07 9.9999999999999995e-07" pos="0 0.20000000000000001 -0.59140000000000004" euler="0 0 180"/>
      <body pos="0 0.20000000000000001 -0.59140000000000004" euler="0 0 180" name="left_tire/">
        <body name="left_tire/body_tire_left">
          <geom name="left_tire/geom_tire_left" class="robot/" type="cylinder" condim="6" priority="1" size="0.1016 0.029999999999999999" friction="0.25 0.0050000000000000001 0.0001" mass="0.34999999999999998" pos="0 -0.029999999999999999 0" euler="90 0 0"/>
          <joint name="left_tire/joint_tire_left" class="robot/" type="hinge" axis="0 1 0" damping="0.25"/>
        </body>
      </body>
      <inertial pos="0 0 0" mass="7.5" diaginertia="0.087800000000000003 0.034700000000000002 0.063200000000000006"/>
      <freejoint name="free_floating_chassis_"/>
      <body name="additional_wheel0" pos="0.2175 0 -0.17999999999999999" euler="0 0 0">
        <geom name="geom_aux_wheel0" class="robot/" type="sphere" size="0.0025000000000000001" rgba="100 0 100 1" mass="0.0001"/>
        <joint name="joint_aux_wheel0" class="robot/" type="ball" pos="0 0 0" damping="0"/>
      </body>
      <body name="additional_wheel1" pos="-0.2175 0 -0.17999999999999999" euler="0 0 0">
        <geom name="geom_aux_wheel1" class="robot/" type="sphere" size="0.0025000000000000001" rgba="100 0 100 1" mass="0.0001"/>
        <joint name="joint_aux_wheel1" class="robot/" type="ball" pos="0 0 0" damping="0"/>
      </body>
      <site name="imu" class="robot/" size="9.9999999999999995e-07 9.9999999999999995e-07 9.9999999999999995e-07" pos="0 0 0"/>
    </body>
    <light name="spotlight_0" class="robot/" mode="targetbodycom" target="body_chassis_" pos="0.11 0.21000000000000002 0.23000000000000001"/>
    <light name="spotlight_1" class="robot/" mode="targetbodycom" target="body_chassis_" pos="0.11 -0.21000000000000002 0.23000000000000001"/>
    <light name="spotlight_2" class="robot/" mode="targetbodycom" target="body_chassis_" pos="-0.11 0.21000000000000002 0.23000000000000001"/>
    <light name="spotlight_3" class="robot/" mode="targetbodycom" target="body_chassis_" pos="-0.11 -0.21000000000000002 0.23000000000000001"/>
  </worldbody>
  <actuator>
    <motor name="left_tire/act" class="robot/" ctrllimited="true" ctrlrange="-5 5" joint="left_tire/joint_tire_left"/>
    <motor name="right_tire/act" class="robot/" ctrllimited="true" ctrlrange="-5 5" joint="right_tire/joint_tire_right"/>
  </actuator>
  <sensor>
    <gyro name="_gyro" site="imu"/>
    <accelerometer name="_accelerometer" site="imu"/>
    <magnetometer name="_magnetometer" site="imu"/>
    <framequat name="_orientation" objtype="site" objname="imu"/>
    <jointpos name="left_tire/pos" noise="0.080000000000000002" joint="left_tire/joint_tire_left"/>
    <jointvel name="left_tire/vel" noise="0.080000000000000002" joint="left_tire/joint_tire_left"/>
    <jointpos name="right_tire/pos" noise="0.080000000000000002" joint="right_tire/joint_tire_right"/>
    <jointvel name="right_tire/vel" noise="0.080000000000000002" joint="right_tire/joint_tire_right"/>
  </sensor>
</mujoco>
