<mujoco model="robot">
  <option apirate="2000"/>
  <default>
    <default class="robot/"/>
    </default>
  <worldbody>
    <body name="body_chassis_" pos="0 0 0" euler="0 0 0">
      <camera name="camera_track_chassis_" class="robot/" mode="track" pos="0 -3 1" zaxis="0 -1 0.5"/>
      <geom name="geom_chassis_" class="robot/" type="box" size="0.22 0.16 0.10000000000000001" rgba="0 0.29999999999999999 0.5 1" mass="15"/>
      <site name="right_site_chassis_" class="robot/" size="9.9999999999999995e-07 9.9999999999999995e-07 9.9999999999999995e-07" pos="0 -0.16 0"/>
      <body pos="0 -0.16 0" name="right_upper_link/">
        <body name="right_upper_link/body_link_right_upper">
          <geom name="right_upper_link/geom_link_right_upper" class="robot/" type="box" size="0.025000000000000001 0.025000000000000001 0.20000000000000001" rgba="0 0.29999999999999999 0.5 1" mass="2" pos="0 -0.025000000000000001 -0.20000000000000001"/>
          <joint name="right_upper_link/joint_link_right_upper" class="robot/" type="hinge" axis="0 1 0" armature="0.010901249999999999" damping="0.023900000000000001" frictionloss="0.13339999999999999"/>
          <site name="right_upper_link/link_out_site_right_upper" class="robot/" size="9.9999999999999995e-07 9.9999999999999995e-07 9.9999999999999995e-07" pos="0 -0.050000000000000003 -0.40000000000000002"/>
          <body pos="0 -0.050000000000000003 -0.40000000000000002" name="right_upper_link/right_down_link/">
            <body name="right_upper_link/right_down_link/body_link_right_down">
              <geom name="right_upper_link/right_down_link/geom_link_right_down" class="robot/" type="box" size="0.025000000000000001 0.025000000000000001 0.20000000000000001" rgba="0 0.29999999999999999 0.5 1" mass="2" pos="0 -0.025000000000000001 -0.20000000000000001"/>
              <joint name="right_upper_link/right_down_link/joint_link_right_down" class="robot/" type="hinge" axis="0 1 0" armature="0.010901249999999999" damping="0.023900000000000001" frictionloss="0.13339999999999999"/>
              <site name="right_upper_link/right_down_link/link_out_site_right_down" class="robot/" size="9.9999999999999995e-07 9.9999999999999995e-07 9.9999999999999995e-07" pos="0 -0.050000000000000003 -0.40000000000000002"/>
              <body pos="0 -0.050000000000000003 -0.40000000000000002" name="right_upper_link/right_down_link/right_tire/">
                <body name="right_upper_link/right_down_link/right_tire/body_tire_right">
                  <geom name="right_upper_link/right_down_link/right_tire/geom_tire_right" class="robot/" type="cylinder" condim="6" priority="1" size="0.082500000000000004 0.029999999999999999" rgba="0 0.29999999999999999 0.5 1" friction="0.94999999999999996 0.0050000000000000001 0.0001" mass="1" pos="0 -0.029999999999999999 0" euler="90 0 0"/>
                  <joint name="right_upper_link/right_down_link/right_tire/joint_tire_right" class="robot/" type="hinge" axis="0 1 0" damping="0.023900000000000001"/>
                </body>
              </body>
            </body>
          </body>
        </body>
      </body>
      <site name="left_site_chassis_" class="robot/" size="9.9999999999999995e-07 9.9999999999999995e-07 9.9999999999999995e-07" pos="0 0.16 0" euler="0 0 180"/>
      <body pos="0 0.16 0" euler="0 0 180" name="left_upper_link/">
        <body name="left_upper_link/body_link_left_upper">
          <geom name="left_upper_link/geom_link_left_upper" class="robot/" type="box" size="0.025000000000000001 0.025000000000000001 0.20000000000000001" rgba="0 0.29999999999999999 0.5 1" mass="2" pos="0 -0.025000000000000001 -0.20000000000000001"/>
          <joint name="left_upper_link/joint_link_left_upper" class="robot/" type="hinge" axis="0 1 0" damping="0.023900000000000001"/>
          <site name="left_upper_link/link_out_site_left_upper" class="robot/" size="9.9999999999999995e-07 9.9999999999999995e-07 9.9999999999999995e-07" pos="0 -0.050000000000000003 -0.40000000000000002"/>
          <body pos="0 -0.050000000000000003 -0.40000000000000002" name="left_upper_link/left_down_link/">
            <body name="left_upper_link/left_down_link/body_link_left_down">
              <geom name="left_upper_link/left_down_link/geom_link_left_down" class="robot/" type="box" size="0.025000000000000001 0.025000000000000001 0.20000000000000001" rgba="0 0.29999999999999999 0.5 1" mass="2" pos="0 -0.025000000000000001 -0.20000000000000001"/>
              <joint name="left_upper_link/left_down_link/joint_link_left_down" class="robot/" type="hinge" axis="0 1 0" damping="0.023900000000000001"/>
              <site name="left_upper_link/left_down_link/link_out_site_left_down" class="robot/" size="9.9999999999999995e-07 9.9999999999999995e-07 9.9999999999999995e-07" pos="0 -0.050000000000000003 -0.40000000000000002"/>
              <body pos="0 -0.050000000000000003 -0.40000000000000002" name="left_upper_link/left_down_link/left_tire/">
                <body name="left_upper_link/left_down_link/left_tire/body_tire_left">
                  <geom name="left_upper_link/left_down_link/left_tire/geom_tire_left" class="robot/" type="cylinder" condim="6" priority="1" size="0.082500000000000004 0.029999999999999999" rgba="0 0.29999999999999999 0.5 1" friction="0.94999999999999996 0.0050000000000000001 0.0001" mass="1" pos="0 -0.029999999999999999 0" euler="90 0 0"/>
                  <joint name="left_upper_link/left_down_link/left_tire/joint_tire_left" class="robot/" type="hinge" axis="0 1 0" damping="0.023900000000000001"/>
                </body>
              </body>
            </body>
          </body>
        </body>
      </body>
      <freejoint name="free_floating_chassis_"/>
      <site name="imu" class="robot/" size="9.9999999999999995e-07 9.9999999999999995e-07 9.9999999999999995e-07" pos="0 0 0"/>
    </body>
    <light name="spotlight_0" class="robot/" mode="targetbodycom" target="body_chassis_" pos="0.25 0.19 0.15000000000000002"/>
    <light name="spotlight_1" class="robot/" mode="targetbodycom" target="body_chassis_" pos="0.25 -0.19 0.15000000000000002"/>
    <light name="spotlight_2" class="robot/" mode="targetbodycom" target="body_chassis_" pos="-0.25 0.19 0.15000000000000002"/>
    <light name="spotlight_3" class="robot/" mode="targetbodycom" target="body_chassis_" pos="-0.25 -0.19 0.15000000000000002"/>
  </worldbody>
  <actuator>
    <position kp="200" kv="20" name="right_upper_link/act" class="robot/" ctrllimited="true" forcelimited="true" ctrlrange="-50 50" forcerange="-50 50" joint="right_upper_link/joint_link_right_upper"/>
    <position kp="200" kv="20" name="right_upper_link/right_down_link/act" class="robot/" ctrllimited="true" forcelimited="true" ctrlrange="-50 50" forcerange="-50 50" joint="right_upper_link/right_down_link/joint_link_right_down"/>
    <velocity kv="100" gear="0.04" name="right_upper_link/right_down_link/right_tire/act" class="robot/" ctrllimited="true" ctrlrange="-50 50" joint="right_upper_link/right_down_link/right_tire/joint_tire_right"/>
    <position kp="200" kv="20" name="left_upper_link/act" class="robot/" ctrllimited="true" forcelimited="true" ctrlrange="-50 50" forcerange="-50 50" joint="left_upper_link/joint_link_left_upper"/>
    <position kp="200" kv="20" name="left_upper_link/left_down_link/act" class="robot/" ctrllimited="true" forcelimited="true" ctrlrange="-50 50" forcerange="-50 50" joint="left_upper_link/left_down_link/joint_link_left_down"/>
    <velocity kv="100" gear="0.04" name="left_upper_link/left_down_link/left_tire/act" class="robot/" ctrllimited="true" ctrlrange="-50 50" joint="left_upper_link/left_down_link/left_tire/joint_tire_left"/>
  </actuator>
  <sensor>
    <gyro name="_gyro" site="imu"/>
    <accelerometer name="_accelerometer" site="imu"/>
    <magnetometer name="_magnetometer" site="imu"/>
    <framequat name="_orientation" objtype="site" objname="imu"/>
    <jointpos name="right_upper_link/pos" joint="right_upper_link/joint_link_right_upper"/>
    <jointvel name="right_upper_link/vel" joint="right_upper_link/joint_link_right_upper"/>
    <jointpos name="right_upper_link/right_down_link/pos" joint="right_upper_link/right_down_link/joint_link_right_down"/>
    <jointvel name="right_upper_link/right_down_link/vel" joint="right_upper_link/right_down_link/joint_link_right_down"/>
    <jointpos name="right_upper_link/right_down_link/right_tire/pos" joint="right_upper_link/right_down_link/right_tire/joint_tire_right"/>
    <jointvel name="right_upper_link/right_down_link/right_tire/vel" joint="right_upper_link/right_down_link/right_tire/joint_tire_right"/>
    <jointpos name="left_upper_link/pos" joint="left_upper_link/joint_link_left_upper"/>
    <jointvel name="left_upper_link/vel" joint="left_upper_link/joint_link_left_upper"/>
    <jointpos name="left_upper_link/left_down_link/pos" joint="left_upper_link/left_down_link/joint_link_left_down"/>
    <jointvel name="left_upper_link/left_down_link/vel" joint="left_upper_link/left_down_link/joint_link_left_down"/>
    <jointpos name="left_upper_link/left_down_link/left_tire/pos" joint="left_upper_link/left_down_link/left_tire/joint_tire_left"/>
    <jointvel name="left_upper_link/left_down_link/left_tire/vel" joint="left_upper_link/left_down_link/left_tire/joint_tire_left"/>
  </sensor>
<keyframe><key time="0" name="init" qpos="0.0 0.0 0.6481854249492381 1.0 0.0 0.0 0.0 0.7853981633974483 -1.5707963267948966 0.0 -0.7853981633974483 1.5707963267948966 0.0"/></keyframe></mujoco>
